using System;

class Program
{
    static void Main()
    {
        try
        {
            Console.WriteLine("Outer Try Block Start");

            try
            {
                Console.WriteLine("Inner Try Block Start");

                // Simulate an exception in the inner block
                throw new InvalidOperationException("Exception in Inner Try Block");
                
                Console.WriteLine("Inner Try Block End"); // This line won't be executed due to the exception
            }
            catch (Exception innerException)
            {
                // Catch the exception thrown in the inner block
                Console.WriteLine("Inner Catch Block: " + innerException.Message);
            }

            Console.WriteLine("Outer Try Block End"); // This line will be executed even after the exception in the inner block
        }
        catch (Exception outerException)
        {
            // Catch any exceptions thrown in the outer block or unhandled exceptions from the inner block
            Console.WriteLine("Outer Catch Block: " + outerException.Message);
        }
    }
}
